Workbook

Sheet 01 Traffic inputs
A1: Sensor 78 | traffic inputs
A2: Yellow cells are inputs. Prepared average weekday from 16 complete January 2016 weekdays; fixed 14:45–19:30 window. Counts are assumed per represented lane.
A6: Traffic input | B6: Value | C6: Unit | D6: Meaning
A7: Detector | B7: 78 | C7: ID | D7: Worked example; AZ I-10 westbound detector 78.
A8: Link length L | B8: 1.04 | C8: mi | D8: Upstream detector spacing.
A9: Capacity C | B9: 1501.6157 | C9: veh/h/lane | D9: Retained detector calibration.
A10: Free-flow speed vf | B10: 64.161375 | C10: mph | D10: Retained detector calibration.
A11: Jam density kj | B11: 220 | C11: veh/mi/lane | D11: Fixed traffic assumption.
A12: Duration coefficient fd | B12: 1.6931766 | C12: h^(1-n) | D12: PM corridor-direction calibration.
A13: Duration exponent n | B13: 0.83303119 | C13: dimensionless | D13: PM corridor-direction calibration.
A14: Delay coefficient fp | B14: 0.30807047 | C14: h^(-s) | D14: PM corridor-direction calibration.
A15: Delay exponent s | B15: 1.6350981 | C15: dimensionless | D15: PM corridor-direction calibration.
A16: Mean / peak delay θ | B16: 0.43482937 | C16: dimensionless | D16: Mean delay divided by peak delay.
A17: Time step | B17: 5 | C17: min | D17: Fixed input time step.
A18: Start hour (fixed) | B18: 14.75 | C18: h | D18: Fixed selected episode start, inclusive.
... A22: Cubic maximum speed | B22: 75 | C22: mph | D22: Upper fitted cubic-rate limit.
A24: Inputs are already averaged; changing them recalculates emissions but does not redetect episode boundaries or refit traffic parameters. All traffic is evaluated with the supplied passenger-car rates. No external files are needed.
A28: Clock time | B28: Count / 5 min | C28: Speed (mph)
A29: 0.61458333 | B29: 125.54167 | C29: 51.62435
A30: 0.61805556 | B30: 120.22917 | C30: 49.299378
A31: 0.62152778 | B31: 116.20833 | C31: 48.463764
A32: 0.625 | B32: 109.89583 | C32: 48.481701
A33: 0.62847222 | B33: 106.89583 | C33: 47.163019
A34: 0.63194444 | B34: 104.52083 | C34: 45.765522
A35: 0.63541667 | B35: 102.27083 | C35: 43.751542
A36: 0.63888889 | B36: 102.875 | C36: 43.237921
A37: 0.64236111 | B37: 99.375 | C37: 42.407266
A38: 0.64583333 | B38: 99.3125 | C38: 41.238866
A39: 0.64930556 | B39: 94.520833 | C39: 38.30714
A40: 0.65277778 | B40: 91.5625 | C40: 33.813086
... A85: 0.80902778 | B85: 87.625 | C85: 62.606097
A88: Numerical integration inputs below: fixed 384-node Gauss–Legendre rule on [0,1]. These are calculation settings, not additional detector observations.
A94: Node | B94: Position u | C94: Weight
A95: 1 | B95: 9.7794137e-06 | C95: 2.5097052e-05
A96: 2 | B96: 5.1526431e-05 | C96: 5.8419533e-05
A97: 3 | B97: 0.00012662959 | C97: 9.178746e-05
A98: 4 | B98: 0.00023510057 | C98: 0.00012515354
A99: 5 | B99: 0.00037693417 | C99: 0.00015851213
A100: 6 | B100: 0.0005521214 | C100: 0.0001918604
A101: 7 | B101: 0.00076065073 | C101: 0.00022519596
...

Sheet 02 Emission rates
A1: Emission inputs | positive-speed lookup
A2: Passenger-car, zero-acceleration, level-road rates, already averaged over the original vehicle-age mixture. Select the last lower-speed boundary not exceeding the speed; no interpolation.
A6: Lower speed (mph) | B6: Upper speed (mph) | C6: VSP at lower speed (kW/t) | D6: CO₂ rate (g/veh·h) | E6: NOₓ rate (g/veh·h) | F6: CO rate (g/veh·h) | G6: HC rate (g/veh·h)
A7: 0 | B7: 25 | C7: 0 | D7: 6931.8463 | E7: 4.0758788 | F7: 62.680628 | G7: 2.7514068
A8: 25 | B8: 33.457591 | C8: 1.8165725 | D8: 7854.4376 | E8: 6.0728067 | F8: 70.349022 | G8: 3.0627468
A9: 33.457591 | B9: 47.32925 | C9: 3 | D9: 9725.595 | E9: 9.2521191 | F9: 91.705804 | G9: 3.6129594
A10: 47.32925 | B10: 50 | C10: 6 | D10: 12537.329 | E10: 15.864045 | F10: 136.02153 | G10: 4.8429828
A11: 50 | B11: 64.140065 | C11: 6.7615245 | D11: 15845.528 | E11: 20.885655 | F11: 98.655406 | G11: 4.4998306
A12: 64.140065 | B12: 75.630658 | C12: 12 | D12: 20615.635 | E12: 30.344373 | F12: 135.13776 | G12: 5.47023
A13: 75.630658 | B13: 84.656535 | C13: 18 | D13: 26856.071 | E13: 45.165407 | F13: 357.36036 | G13: 10.447323
A14: 84.656535 | B14: 92.214456 | C14: 24 | D14: 35744.61 | E14: 64.064568 | F14: 478.84673 | G14: 15.307288
A15: 92.214456 | B15: ∞ | C15: 30 | D15: 45530.43 | E15: 80.06862 | F15: 1233.924 | G15: 21.085012
A18: First band: 0 < speed < 25 mph. Other lower bounds are inclusive; upper bounds are exclusive. Zero speed is not supported by this moving-vehicle table. Editing these rates updates O/S/R/M; A uses its separately supplied cubic coefficients.

Sheet 03 Recorded O
A1: O | recorded five-minute speeds
A2: Five-minute emissions are full-link emissions assigned to vehicles counted in that interval, not exhaust physically released during those five minutes. Effective rate = bin emissions / bin vehicle-hours.
A6: Per bin: trip time = L / recorded speed; vehicle-hours = count × trip time; emissions = vehicle-hours × lookup rate. This is the modeled comparison reference, not measured exhaust.
A8: The prepared input speeds use count-weighted harmonic averaging across the 16 retained weekdays. The supplied spreadsheet’s separate travel-time field is not used; travel time is calculated from link length and speed.
A10: Clock time | B10: Count / 5 min | C10: Mean trip time (min) | D10: Effective speed (mph) | E10: Vehicle-hours | F10: CO₂ effective rate (g/veh·h) | G10: CO₂ / 5 min (g) | H10: NOₓ effective rate | I10: NOₓ / 5 min (g) | J10: CO effective rate | K10: CO / 5 min (g) | L10: HC effective rate | M10: HC / 5 min (g)
A11: ='01 Traffic inputs'!A29 -> 0.61458333 | B11: ='01 Traffic inputs'!B29*'01 Traffic inputs'!$B$20 -> 125.54167 | C11: ='01 Traffic inputs'!$B$8/D11*60 -> 1.2087319 | D11: ='01 Traffic inputs'!C29 -> 51.62435 | E11: =B11*C11/60 -> 2.5291037 | F11: =IF(D11>0,INDEX('02 Emission rates'!$D$7:$D$15,MATCH(D11,'02 Emission rates'!$A$7:$A$15,1)),NA()) -> 15845.528 | G11: =E11*F11 -> 40074.983 | H11: =IF(D11>0,INDEX('02 Emission rates'!$E$7:$E$15,MATCH(D11,'02 Emission rates'!$A$7:$A$15,1)),NA()) -> 20.885655 | I11: =E11*H11 -> 52.821986 | J11: =IF(D11>0,INDEX('02 Emission rates'!$F$7:$F$15,MATCH(D11,'02 Emission rates'!$A$7:$A$15,1)),NA()) -> 98.655406 | K11: =E11*J11 -> 249.50975 | L11: =IF(D11>0,INDEX('02 Emission rates'!$G$7:$G$15,MATCH(D11,'02 Emission rates'!$A$7:$A$15,1)),NA()) -> 4.4998306 | M11: =E11*L11 -> 11.380538
A12: ='01 Traffic inputs'!A30 -> 0.61805556 | B12: ='01 Traffic inputs'!B30*'01 Traffic inputs'!$B$20 -> 120.22917 | C12: ='01 Traffic inputs'!$B$8/D12*60 -> 1.265736 | D12: ='01 Traffic inputs'!C30 -> 49.299378 | E12: =B12*C12/60 -> 2.5363065 | F12: =IF(D12>0,INDEX('02 Emission rates'!$D$7:$D$15,MATCH(D12,'02 Emission rates'!$A$7:$A$15,1)),NA()) -> 12537.329 | G12: =E12*F12 -> 31798.51 | H12: =IF(D12>0,INDEX('02 Emission rates'!$E$7:$E$15,MATCH(D12,'02 Emission rates'!$A$7:$A$15,1)),NA()) -> 15.864045 | I12: =E12*H12 -> 40.236081 | J12: =IF(D12>0,INDEX('02 Emission rates'!$F$7:$F$15,MATCH(D12,'02 Emission rates'!$A$7:$A$15,1)),NA()) -> 136.02153 | K12: =E12*J12 -> 344.9923 | L12: =IF(D12>0,INDEX('02 Emission rates'!$G$7:$G$15,MATCH(D12,'02 Emission rates'!$A$7:$A$15,1)),NA()) -> 4.8429828 | M12: =E12*L12 -> 12.283289
A13: ='01 Traffic inputs'!A31 -> 0.62152778 | B13: ='01 Traffic inputs'!B31*'01 Traffic inputs'!$B$20 -> 116.20833 | C13: ='01 Traffic inputs'!$B$8/D13*60 -> 1.2875599 | D13: ='01 Traffic inputs'!C31 -> 48.463764 | E13: =B13*C13/60 -> 2.4937532 | F13: =IF(D13>0,INDEX('02 Emission rates'!$D$7:$D$15,MATCH(D13,'02 Emission rates'!$A$7:$A$15,1)),NA()) -> 12537.329 | G13: =E13*F13 -> 31265.005 | H13: =IF(D13>0,INDEX('02 Emission rates'!$E$7:$E$15,MATCH(D13,'02 Emission rates'!$A$7:$A$15,1)),NA()) -> 15.864045 | I13: =E13*H13 -> 39.561013 | J13: =IF(D13>0,INDEX('02 Emission rates'!$F$7:$F$15,MATCH(D13,'02 Emission rates'!$A$7:$A$15,1)),NA()) -> 136.02153 | K13: =E13*J13 -> 339.20413 | L13: =IF(D13>0,INDEX('02 Emission rates'!$G$7:$G$15,MATCH(D13,'02 Emission rates'!$A$7:$A$15,1)),NA()) -> 4.8429828 | M13: =E13*L13 -> 12.077204
A14: ='01 Traffic inputs'!A32 -> 0.625 | B14: ='01 Traffic inputs'!B32*'01 Traffic inputs'!$B$20 -> 109.89583 | C14: ='01 Traffic inputs'!$B$8/D14*60 -> 1.2870835 | D14: ='01 Traffic inputs'!C32 -> 48.481701 | E14: =B14*C14/60 -> 2.3574186 | F14: =IF(D14>0,INDEX('02 Emission rates'!$D$7:$D$15,MATCH(D14,'02 Emission rates'!$A$7:$A$15,1)),NA()) -> 12537.329 | G14: =E14*F14 -> 29555.734 | H14: =IF(D14>0,INDEX('02 Emission rates'!$E$7:$E$15,MATCH(D14,'02 Emission rates'!$A$7:$A$15,1)),NA()) -> 15.864045 | I14: =E14*H14 -> 37.398196 | J14: =IF(D14>0,INDEX('02 Emission rates'!$F$7:$F$15,MATCH(D14,'02 Emission rates'!$A$7:$A$15,1)),NA()) -> 136.02153 | K14: =E14*J14 -> 320.6597 | L14: =IF(D14>0,INDEX('02 Emission rates'!$G$7:$G$15,MATCH(D14,'02 Emission rates'!$A$7:$A$15,1)),NA()) -> 4.8429828 | M14: =E14*L14 -> 11.416938
A15: ='01 Traffic inputs'!A33 -> 0.62847222 | B15: ='01 Traffic inputs'!B33*'01 Traffic inputs'!$B$20 -> 106.89583 | C15: ='01 Traffic inputs'!$B$8/D15*60 -> 1.3230705 | D15: ='01 Traffic inputs'!C33 -> 47.163019 | E15: =B15*C15/60 -> 2.3571787 | F15: =IF(D15>0,INDEX('02 Emission rates'!$D$7:$D$15,MATCH(D15,'02 Emission rates'!$A$7:$A$15,1)),NA()) -> 9725.595 | G15: =E15*F15 -> 22924.966 | H15: =IF(D15>0,INDEX('02 Emission rates'!$E$7:$E$15,MATCH(D15,'02 Emission rates'!$A$7:$A$15,1)),NA()) -> 9.2521191 | I15: =E15*H15 -> 21.808898 | J15: =IF(D15>0,INDEX('02 Emission rates'!$F$7:$F$15,MATCH(D15,'02 Emission rates'!$A$7:$A$15,1)),NA()) -> 91.705804 | K15: =E15*J15 -> 216.16697 | L15: =IF(D15>0,INDEX('02 Emission rates'!$G$7:$G$15,MATCH(D15,'02 Emission rates'!$A$7:$A$15,1)),NA()) -> 3.6129594 | M15: =E15*L15 -> 8.516391
A16: ='01 Traffic inputs'!A34 -> 0.63194444 | B16: ='01 Traffic inputs'!B34*'01 Traffic inputs'!$B$20 -> 104.52083 | C16: ='01 Traffic inputs'!$B$8/D16*60 -> 1.3634718 | D16: ='01 Traffic inputs'!C34 -> 45.765522 | E16: =B16*C16/60 -> 2.3751869 | F16: =IF(D16>0,INDEX('02 Emission rates'!$D$7:$D$15,MATCH(D16,'02 Emission rates'!$A$7:$A$15,1)),NA()) -> 9725.595 | G16: =E16*F16 -> 23100.105 | H16: =IF(D16>0,INDEX('02 Emission rates'!$E$7:$E$15,MATCH(D16,'02 Emission rates'!$A$7:$A$15,1)),NA()) -> 9.2521191 | I16: =E16*H16 -> 21.975512 | J16: =IF(D16>0,INDEX('02 Emission rates'!$F$7:$F$15,MATCH(D16,'02 Emission rates'!$A$7:$A$15,1)),NA()) -> 91.705804 | K16: =E16*J16 -> 217.81842 | L16: =IF(D16>0,INDEX('02 Emission rates'!$G$7:$G$15,MATCH(D16,'02 Emission rates'!$A$7:$A$15,1)),NA()) -> 3.6129594 | M16: =E16*L16 -> 8.5814536
A17: ='01 Traffic inputs'!A35 -> 0.63541667 | B17: ='01 Traffic inputs'!B35*'01 Traffic inputs'!$B$20 -> 102.27083 | C17: ='01 Traffic inputs'!$B$8/D17*60 -> 1.4262354 | D17: ='01 Traffic inputs'!C35 -> 43.751542 | E17: =B17*C17/60 -> 2.4310381 | F17: =IF(D17>0,INDEX('02 Emission rates'!$D$7:$D$15,MATCH(D17,'02 Emission rates'!$A$7:$A$15,1)),NA()) -> 9725.595 | G17: =E17*F17 -> 23643.292 | H17: =IF(D17>0,INDEX('02 Emission rates'!$E$7:$E$15,MATCH(D17,'02 Emission rates'!$A$7:$A$15,1)),NA()) -> 9.2521191 | I17: =E17*H17 -> 22.492254 | J17: =IF(D17>0,INDEX('02 Emission rates'!$F$7:$F$15,MATCH(D17,'02 Emission rates'!$A$7:$A$15,1)),NA()) -> 91.705804 | K17: =E17*J17 -> 222.94031 | L17: =IF(D17>0,INDEX('02 Emission rates'!$G$7:$G$15,MATCH(D17,'02 Emission rates'!$A$7:$A$15,1)),NA()) -> 3.6129594 | M17: =E17*L17 -> 8.783242
A18: ='01 Traffic inputs'!A36 -> 0.63888889 | B18: ='01 Traffic inputs'!B36*'01 Traffic inputs'!$B$20 -> 102.875 | C18: ='01 Traffic inputs'!$B$8/D18*60 -> 1.4431776 | D18: ='01 Traffic inputs'!C36 -> 43.237921 | E18: =B18*C18/60 -> 2.4744483 | F18: =IF(D18>0,INDEX('02 Emission rates'!$D$7:$D$15,MATCH(D18,'02 Emission rates'!$A$7:$A$15,1)),NA()) -> 9725.595 | G18: =E18*F18 -> 24065.482 | H18: =IF(D18>0,INDEX('02 Emission rates'!$E$7:$E$15,MATCH(D18,'02 Emission rates'!$A$7:$A$15,1)),NA()) -> 9.2521191 | I18: =E18*H18 -> 22.89389 | J18: =IF(D18>0,INDEX('02 Emission rates'!$F$7:$F$15,MATCH(D18,'02 Emission rates'!$A$7:$A$15,1)),NA()) -> 91.705804 | K18: =E18*J18 -> 226.92127 | L18: =IF(D18>0,INDEX('02 Emission rates'!$G$7:$G$15,MATCH(D18,'02 Emission rates'!$A$7:$A$15,1)),NA()) -> 3.6129594 | M18: =E18*L18 -> 8.9400812
A19: ='01 Traffic inputs'!A37 -> 0.64236111 | B19: ='01 Traffic inputs'!B37*'01 Traffic inputs'!$B$20 -> 99.375 | C19: ='01 Traffic inputs'!$B$8/D19*60 -> 1.471446 | D19: ='01 Traffic inputs'!C37 -> 42.407266 | E19: =B19*C19/60 -> 2.4370824 | F19: =IF(D19>0,INDEX('02 Emission rates'!$D$7:$D$15,MATCH(D19,'02 Emission rates'!$A$7:$A$15,1)),NA()) -> 9725.595 | G19: =E19*F19 -> 23702.076 | H19: =IF(D19>0,INDEX('02 Emission rates'!$E$7:$E$15,MATCH(D19,'02 Emission rates'!$A$7:$A$15,1)),NA()) -> 9.2521191 | I19: =E19*H19 -> 22.548176 | J19: =IF(D19>0,INDEX('02 Emission rates'!$F$7:$F$15,MATCH(D19,'02 Emission rates'!$A$7:$A$15,1)),NA()) -> 91.705804 | K19: =E19*J19 -> 223.4946 | L19: =IF(D19>0,INDEX('02 Emission rates'!$G$7:$G$15,MATCH(D19,'02 Emission rates'!$A$7:$A$15,1)),NA()) -> 3.6129594 | M19: =E19*L19 -> 8.8050796
A20: ='01 Traffic inputs'!A38 -> 0.64583333 | B20: ='01 Traffic inputs'!B38*'01 Traffic inputs'!$B$20 -> 99.3125 | C20: ='01 Traffic inputs'!$B$8/D20*60 -> 1.5131357 | D20: ='01 Traffic inputs'!C38 -> 41.238866 | E20: =B20*C20/60 -> 2.5045548 | F20: =IF(D20>0,INDEX('02 Emission rates'!$D$7:$D$15,MATCH(D20,'02 Emission rates'!$A$7:$A$15,1)),NA()) -> 9725.595 | G20: =E20*F20 -> 24358.285 | H20: =IF(D20>0,INDEX('02 Emission rates'!$E$7:$E$15,MATCH(D20,'02 Emission rates'!$A$7:$A$15,1)),NA()) -> 9.2521191 | I20: =E20*H20 -> 23.172439 | J20: =IF(D20>0,INDEX('02 Emission rates'!$F$7:$F$15,MATCH(D20,'02 Emission rates'!$A$7:$A$15,1)),NA()) -> 91.705804 | K20: =E20*J20 -> 229.68221 | L20: =IF(D20>0,INDEX('02 Emission rates'!$G$7:$G$15,MATCH(D20,'02 Emission rates'!$A$7:$A$15,1)),NA()) -> 3.6129594 | M20: =E20*L20 -> 9.0488546
A21: ='01 Traffic inputs'!A39 -> 0.64930556 | B21: ='01 Traffic inputs'!B39*'01 Traffic inputs'!$B$20 -> 94.520833 | C21: ='01 Traffic inputs'!$B$8/D21*60 -> 1.6289392 | D21: ='01 Traffic inputs'!C39 -> 38.30714 | E21: =B21*C21/60 -> 2.5661448 | F21: =IF(D21>0,INDEX('02 Emission rates'!$D$7:$D$15,MATCH(D21,'02 Emission rates'!$A$7:$A$15,1)),NA()) -> 9725.595 | G21: =E21*F21 -> 24957.285 | H21: =IF(D21>0,INDEX('02 Emission rates'!$E$7:$E$15,MATCH(D21,'02 Emission rates'!$A$7:$A$15,1)),NA()) -> 9.2521191 | I21: =E21*H21 -> 23.742277 | J21: =IF(D21>0,INDEX('02 Emission rates'!$F$7:$F$15,MATCH(D21,'02 Emission rates'!$A$7:$A$15,1)),NA()) -> 91.705804 | K21: =E21*J21 -> 235.33037 | L21: =IF(D21>0,INDEX('02 Emission rates'!$G$7:$G$15,MATCH(D21,'02 Emission rates'!$A$7:$A$15,1)),NA()) -> 3.6129594 | M21: =E21*L21 -> 9.2713768
A22: ='01 Traffic inputs'!A40 -> 0.65277778 | B22: ='01 Traffic inputs'!B40*'01 Traffic inputs'!$B$20 -> 91.5625 | C22: ='01 Traffic inputs'!$B$8/D22*60 -> 1.8454394 | D22: ='01 Traffic inputs'!C40 -> 33.813086 | E22: =B22*C22/60 -> 2.8162174 | F22: =IF(D22>0,INDEX('02 Emission rates'!$D$7:$D$15,MATCH(D22,'02 Emission rates'!$A$7:$A$15,1)),NA()) -> 9725.595 | G22: =E22*F22 -> 27389.389 | H22: =IF(D22>0,INDEX('02 Emission rates'!$E$7:$E$15,MATCH(D22,'02 Emission rates'!$A$7:$A$15,1)),NA()) -> 9.2521191 | I22: =E22*H22 -> 26.055978 | J22: =IF(D22>0,INDEX('02 Emission rates'!$F$7:$F$15,MATCH(D22,'02 Emission rates'!$A$7:$A$15,1)),NA()) -> 91.705804 | K22: =E22*J22 -> 258.26348 | L22: =IF(D22>0,INDEX('02 Emission rates'!$G$7:$G$15,MATCH(D22,'02 Emission rates'!$A$7:$A$15,1)),NA()) -> 3.6129594 | M22: =E22*L22 -> 10.174879
... A67: ='01 Traffic inputs'!A85 -> 0.80902778 | B67: ='01 Traffic inputs'!B85*'01 Traffic inputs'!$B$20 -> 87.625 | C67: ='01 Traffic inputs'!$B$8/D67*60 -> 0.99670804 | D67: ='01 Traffic inputs'!C85 -> 62.606097 | E67: =B67*C67/60 -> 1.455609 | F67: =IF(D67>0,INDEX('02 Emission rates'!$D$7:$D$15,MATCH(D67,'02 Emission rates'!$A$7:$A$15,1)),NA()) -> 15845.528 | G67: =E67*F67 -> 23064.894 | H67: =IF(D67>0,INDEX('02 Emission rates'!$E$7:$E$15,MATCH(D67,'02 Emission rates'!$A$7:$A$15,1)),NA()) -> 20.885655 | I67: =E67*H67 -> 30.401347 | J67: =IF(D67>0,INDEX('02 Emission rates'!$F$7:$F$15,MATCH(D67,'02 Emission rates'!$A$7:$A$15,1)),NA()) -> 98.655406 | K67: =E67*J67 -> 143.6037 | L67: =IF(D67>0,INDEX('02 Emission rates'!$G$7:$G$15,MATCH(D67,'02 Emission rates'!$A$7:$A$15,1)),NA()) -> 4.4998306 | M67: =E67*L67 -> 6.549994
A69: Total / mean | B69: =SUM(B11:B67) -> 4789.25 | C69: =E69/B69*60 -> 2.6488568 | D69: =B69*'01 Traffic inputs'!$B$8/E69 -> 23.557332 | E69: =SUM(E11:E67) -> 211.43396 | F69: =G69/E69 -> 8247.4331 | G69: =SUM(G11:G67) -> 1743787.4 | H69: =I69/E69 -> 6.6253227 | I69: =SUM(I11:I67) -> 1400.8182 | J69: =K69/E69 -> 73.363241 | K69: =SUM(K11:K67) -> 15511.48 | L69: =M69/E69 -> 3.1152097 | M69: =SUM(M11:M67) -> 658.66112

Sheet 04 Mean speed S
A1: S | observed mean speed
A2: Five-minute emissions are full-link emissions assigned to vehicles counted in that interval, not exhaust physically released during those five minutes. Effective rate = bin emissions / bin vehicle-hours.
A4: Mean speed | B4: ='03 Recorded O'!D69 -> 23.557332 | C4: mph
A5: Mean speed = total vehicle-distance / observed vehicle-hours. Every group uses that same trip speed. This method inherits the recorded reference’s total travel time; it is not an independent delay prediction.
A8: Clock time | B8: Count / 5 min | C8: Mean trip time (min) | D8: Effective speed (mph) | E8: Vehicle-hours | F8: CO₂ effective rate (g/veh·h) | G8: CO₂ / 5 min (g) | H8: NOₓ effective rate | I8: NOₓ / 5 min (g) | J8: CO effective rate | K8: CO / 5 min (g) | L8: HC effective rate | M8: HC / 5 min (g)
A9: ='03 Recorded O'!A11 -> 0.61458333 | B9: ='03 Recorded O'!B11 -> 125.54167 | C9: ='01 Traffic inputs'!$B$8/D9*60 -> 2.6488568 | D9: =$B$4 -> 23.557332 | E9: =B9*C9/60 -> 5.5423649 | F9: =IF(D9>0,INDEX('02 Emission rates'!$D$7:$D$15,MATCH(D9,'02 Emission rates'!$A$7:$A$15,1)),NA()) -> 6931.8463 | G9: =E9*F9 -> 38418.822 | H9: =IF(D9>0,INDEX('02 Emission rates'!$E$7:$E$15,MATCH(D9,'02 Emission rates'!$A$7:$A$15,1)),NA()) -> 4.0758788 | I9: =E9*H9 -> 22.590008 | J9: =IF(D9>0,INDEX('02 Emission rates'!$F$7:$F$15,MATCH(D9,'02 Emission rates'!$A$7:$A$15,1)),NA()) -> 62.680628 | K9: =E9*J9 -> 347.39892 | L9: =IF(D9>0,INDEX('02 Emission rates'!$G$7:$G$15,MATCH(D9,'02 Emission rates'!$A$7:$A$15,1)),NA()) -> 2.7514068 | M9: =E9*L9 -> 15.249301
A10: ='03 Recorded O'!A12 -> 0.61805556 | B10: ='03 Recorded O'!B12 -> 120.22917 | C10: ='01 Traffic inputs'!$B$8/D10*60 -> 2.6488568 | D10: =$B$4 -> 23.557332 | E10: =B10*C10/60 -> 5.3078307 | F10: =IF(D10>0,INDEX('02 Emission rates'!$D$7:$D$15,MATCH(D10,'02 Emission rates'!$A$7:$A$15,1)),NA()) -> 6931.8463 | G10: =E10*F10 -> 36793.067 | H10: =IF(D10>0,INDEX('02 Emission rates'!$E$7:$E$15,MATCH(D10,'02 Emission rates'!$A$7:$A$15,1)),NA()) -> 4.0758788 | I10: =E10*H10 -> 21.634075 | J10: =IF(D10>0,INDEX('02 Emission rates'!$F$7:$F$15,MATCH(D10,'02 Emission rates'!$A$7:$A$15,1)),NA()) -> 62.680628 | K10: =E10*J10 -> 332.69817 | L10: =IF(D10>0,INDEX('02 Emission rates'!$G$7:$G$15,MATCH(D10,'02 Emission rates'!$A$7:$A$15,1)),NA()) -> 2.7514068 | M10: =E10*L10 -> 14.604002
A11: ='03 Recorded O'!A13 -> 0.62152778 | B11: ='03 Recorded O'!B13 -> 116.20833 | C11: ='01 Traffic inputs'!$B$8/D11*60 -> 2.6488568 | D11: =$B$4 -> 23.557332 | E11: =B11*C11/60 -> 5.1303205 | F11: =IF(D11>0,INDEX('02 Emission rates'!$D$7:$D$15,MATCH(D11,'02 Emission rates'!$A$7:$A$15,1)),NA()) -> 6931.8463 | G11: =E11*F11 -> 35562.594 | H11: =IF(D11>0,INDEX('02 Emission rates'!$E$7:$E$15,MATCH(D11,'02 Emission rates'!$A$7:$A$15,1)),NA()) -> 4.0758788 | I11: =E11*H11 -> 20.910565 | J11: =IF(D11>0,INDEX('02 Emission rates'!$F$7:$F$15,MATCH(D11,'02 Emission rates'!$A$7:$A$15,1)),NA()) -> 62.680628 | K11: =E11*J11 -> 321.57171 | L11: =IF(D11>0,INDEX('02 Emission rates'!$G$7:$G$15,MATCH(D11,'02 Emission rates'!$A$7:$A$15,1)),NA()) -> 2.7514068 | M11: =E11*L11 -> 14.115599
A12: ='03 Recorded O'!A14 -> 0.625 | B12: ='03 Recorded O'!B14 -> 109.89583 | C12: ='01 Traffic inputs'!$B$8/D12*60 -> 2.6488568 | D12: =$B$4 -> 23.557332 | E12: =B12*C12/60 -> 4.8516387 | F12: =IF(D12>0,INDEX('02 Emission rates'!$D$7:$D$15,MATCH(D12,'02 Emission rates'!$A$7:$A$15,1)),NA()) -> 6931.8463 | G12: =E12*F12 -> 33630.814 | H12: =IF(D12>0,INDEX('02 Emission rates'!$E$7:$E$15,MATCH(D12,'02 Emission rates'!$A$7:$A$15,1)),NA()) -> 4.0758788 | I12: =E12*H12 -> 19.774692 | J12: =IF(D12>0,INDEX('02 Emission rates'!$F$7:$F$15,MATCH(D12,'02 Emission rates'!$A$7:$A$15,1)),NA()) -> 62.680628 | K12: =E12*J12 -> 304.10376 | L12: =IF(D12>0,INDEX('02 Emission rates'!$G$7:$G$15,MATCH(D12,'02 Emission rates'!$A$7:$A$15,1)),NA()) -> 2.7514068 | M12: =E12*L12 -> 13.348832
A13: ='03 Recorded O'!A15 -> 0.62847222 | B13: ='03 Recorded O'!B15 -> 106.89583 | C13: ='01 Traffic inputs'!$B$8/D13*60 -> 2.6488568 | D13: =$B$4 -> 23.557332 | E13: =B13*C13/60 -> 4.7191959 | F13: =IF(D13>0,INDEX('02 Emission rates'!$D$7:$D$15,MATCH(D13,'02 Emission rates'!$A$7:$A$15,1)),NA()) -> 6931.8463 | G13: =E13*F13 -> 32712.741 | H13: =IF(D13>0,INDEX('02 Emission rates'!$E$7:$E$15,MATCH(D13,'02 Emission rates'!$A$7:$A$15,1)),NA()) -> 4.0758788 | I13: =E13*H13 -> 19.234871 | J13: =IF(D13>0,INDEX('02 Emission rates'!$F$7:$F$15,MATCH(D13,'02 Emission rates'!$A$7:$A$15,1)),NA()) -> 62.680628 | K13: =E13*J13 -> 295.80216 | L13: =IF(D13>0,INDEX('02 Emission rates'!$G$7:$G$15,MATCH(D13,'02 Emission rates'!$A$7:$A$15,1)),NA()) -> 2.7514068 | M13: =E13*L13 -> 12.984428
A14: ='03 Recorded O'!A16 -> 0.63194444 | B14: ='03 Recorded O'!B16 -> 104.52083 | C14: ='01 Traffic inputs'!$B$8/D14*60 -> 2.6488568 | D14: =$B$4 -> 23.557332 | E14: =B14*C14/60 -> 4.6143453 | F14: =IF(D14>0,INDEX('02 Emission rates'!$D$7:$D$15,MATCH(D14,'02 Emission rates'!$A$7:$A$15,1)),NA()) -> 6931.8463 | G14: =E14*F14 -> 31985.933 | H14: =IF(D14>0,INDEX('02 Emission rates'!$E$7:$E$15,MATCH(D14,'02 Emission rates'!$A$7:$A$15,1)),NA()) -> 4.0758788 | I14: =E14*H14 -> 18.807512 | J14: =IF(D14>0,INDEX('02 Emission rates'!$F$7:$F$15,MATCH(D14,'02 Emission rates'!$A$7:$A$15,1)),NA()) -> 62.680628 | K14: =E14*J14 -> 289.23006 | L14: =IF(D14>0,INDEX('02 Emission rates'!$G$7:$G$15,MATCH(D14,'02 Emission rates'!$A$7:$A$15,1)),NA()) -> 2.7514068 | M14: =E14*L14 -> 12.695941
A15: ='03 Recorded O'!A17 -> 0.63541667 | B15: ='03 Recorded O'!B17 -> 102.27083 | C15: ='01 Traffic inputs'!$B$8/D15*60 -> 2.6488568 | D15: =$B$4 -> 23.557332 | E15: =B15*C15/60 -> 4.5150132 | F15: =IF(D15>0,INDEX('02 Emission rates'!$D$7:$D$15,MATCH(D15,'02 Emission rates'!$A$7:$A$15,1)),NA()) -> 6931.8463 | G15: =E15*F15 -> 31297.378 | H15: =IF(D15>0,INDEX('02 Emission rates'!$E$7:$E$15,MATCH(D15,'02 Emission rates'!$A$7:$A$15,1)),NA()) -> 4.0758788 | I15: =E15*H15 -> 18.402647 | J15: =IF(D15>0,INDEX('02 Emission rates'!$F$7:$F$15,MATCH(D15,'02 Emission rates'!$A$7:$A$15,1)),NA()) -> 62.680628 | K15: =E15*J15 -> 283.00386 | L15: =IF(D15>0,INDEX('02 Emission rates'!$G$7:$G$15,MATCH(D15,'02 Emission rates'!$A$7:$A$15,1)),NA()) -> 2.7514068 | M15: =E15*L15 -> 12.422638
A16: ='03 Recorded O'!A18 -> 0.63888889 | B16: ='03 Recorded O'!B18 -> 102.875 | C16: ='01 Traffic inputs'!$B$8/D16*60 -> 2.6488568 | D16: =$B$4 -> 23.557332 | E16: =B16*C16/60 -> 4.5416857 | F16: =IF(D16>0,INDEX('02 Emission rates'!$D$7:$D$15,MATCH(D16,'02 Emission rates'!$A$7:$A$15,1)),NA()) -> 6931.8463 | G16: =E16*F16 -> 31482.267 | H16: =IF(D16>0,INDEX('02 Emission rates'!$E$7:$E$15,MATCH(D16,'02 Emission rates'!$A$7:$A$15,1)),NA()) -> 4.0758788 | I16: =E16*H16 -> 18.511361 | J16: =IF(D16>0,INDEX('02 Emission rates'!$F$7:$F$15,MATCH(D16,'02 Emission rates'!$A$7:$A$15,1)),NA()) -> 62.680628 | K16: =E16*J16 -> 284.67571 | L16: =IF(D16>0,INDEX('02 Emission rates'!$G$7:$G$15,MATCH(D16,'02 Emission rates'!$A$7:$A$15,1)),NA()) -> 2.7514068 | M16: =E16*L16 -> 12.496025
A17: ='03 Recorded O'!A19 -> 0.64236111 | B17: ='03 Recorded O'!B19 -> 99.375 | C17: ='01 Traffic inputs'!$B$8/D17*60 -> 2.6488568 | D17: =$B$4 -> 23.557332 | E17: =B17*C17/60 -> 4.3871691 | F17: =IF(D17>0,INDEX('02 Emission rates'!$D$7:$D$15,MATCH(D17,'02 Emission rates'!$A$7:$A$15,1)),NA()) -> 6931.8463 | G17: =E17*F17 -> 30411.182 | H17: =IF(D17>0,INDEX('02 Emission rates'!$E$7:$E$15,MATCH(D17,'02 Emission rates'!$A$7:$A$15,1)),NA()) -> 4.0758788 | I17: =E17*H17 -> 17.88157 | J17: =IF(D17>0,INDEX('02 Emission rates'!$F$7:$F$15,MATCH(D17,'02 Emission rates'!$A$7:$A$15,1)),NA()) -> 62.680628 | K17: =E17*J17 -> 274.99051 | L17: =IF(D17>0,INDEX('02 Emission rates'!$G$7:$G$15,MATCH(D17,'02 Emission rates'!$A$7:$A$15,1)),NA()) -> 2.7514068 | M17: =E17*L17 -> 12.070887
A18: ='03 Recorded O'!A20 -> 0.64583333 | B18: ='03 Recorded O'!B20 -> 99.3125 | C18: ='01 Traffic inputs'!$B$8/D18*60 -> 2.6488568 | D18: =$B$4 -> 23.557332 | E18: =B18*C18/60 -> 4.3844098 | F18: =IF(D18>0,INDEX('02 Emission rates'!$D$7:$D$15,MATCH(D18,'02 Emission rates'!$A$7:$A$15,1)),NA()) -> 6931.8463 | G18: =E18*F18 -> 30392.055 | H18: =IF(D18>0,INDEX('02 Emission rates'!$E$7:$E$15,MATCH(D18,'02 Emission rates'!$A$7:$A$15,1)),NA()) -> 4.0758788 | I18: =E18*H18 -> 17.870323 | J18: =IF(D18>0,INDEX('02 Emission rates'!$F$7:$F$15,MATCH(D18,'02 Emission rates'!$A$7:$A$15,1)),NA()) -> 62.680628 | K18: =E18*J18 -> 274.81756 | L18: =IF(D18>0,INDEX('02 Emission rates'!$G$7:$G$15,MATCH(D18,'02 Emission rates'!$A$7:$A$15,1)),NA()) -> 2.7514068 | M18: =E18*L18 -> 12.063295
A19: ='03 Recorded O'!A21 -> 0.64930556 | B19: ='03 Recorded O'!B21 -> 94.520833 | C19: ='01 Traffic inputs'!$B$8/D19*60 -> 2.6488568 | D19: =$B$4 -> 23.557332 | E19: =B19*C19/60 -> 4.1728692 | F19: =IF(D19>0,INDEX('02 Emission rates'!$D$7:$D$15,MATCH(D19,'02 Emission rates'!$A$7:$A$15,1)),NA()) -> 6931.8463 | G19: =E19*F19 -> 28925.688 | H19: =IF(D19>0,INDEX('02 Emission rates'!$E$7:$E$15,MATCH(D19,'02 Emission rates'!$A$7:$A$15,1)),NA()) -> 4.0758788 | I19: =E19*H19 -> 17.008109 | J19: =IF(D19>0,INDEX('02 Emission rates'!$F$7:$F$15,MATCH(D19,'02 Emission rates'!$A$7:$A$15,1)),NA()) -> 62.680628 | K19: =E19*J19 -> 261.55806 | L19: =IF(D19>0,INDEX('02 Emission rates'!$G$7:$G$15,MATCH(D19,'02 Emission rates'!$A$7:$A$15,1)),NA()) -> 2.7514068 | M19: =E19*L19 -> 11.481261
A20: ='03 Recorded O'!A22 -> 0.65277778 | B20: ='03 Recorded O'!B22 -> 91.5625 | C20: ='01 Traffic inputs'!$B$8/D20*60 -> 2.6488568 | D20: =$B$4 -> 23.557332 | E20: =B20*C20/60 -> 4.0422658 | F20: =IF(D20>0,INDEX('02 Emission rates'!$D$7:$D$15,MATCH(D20,'02 Emission rates'!$A$7:$A$15,1)),NA()) -> 6931.8463 | G20: =E20*F20 -> 28020.366 | H20: =IF(D20>0,INDEX('02 Emission rates'!$E$7:$E$15,MATCH(D20,'02 Emission rates'!$A$7:$A$15,1)),NA()) -> 4.0758788 | I20: =E20*H20 -> 16.475786 | J20: =IF(D20>0,INDEX('02 Emission rates'!$F$7:$F$15,MATCH(D20,'02 Emission rates'!$A$7:$A$15,1)),NA()) -> 62.680628 | K20: =E20*J20 -> 253.37176 | L20: =IF(D20>0,INDEX('02 Emission rates'!$G$7:$G$15,MATCH(D20,'02 Emission rates'!$A$7:$A$15,1)),NA()) -> 2.7514068 | M20: =E20*L20 -> 11.121918
... A65: ='03 Recorded O'!A67 -> 0.80902778 | B65: ='03 Recorded O'!B67 -> 87.625 | C65: ='01 Traffic inputs'!$B$8/D65*60 -> 2.6488568 | D65: =$B$4 -> 23.557332 | E65: =B65*C65/60 -> 3.8684346 | F65: =IF(D65>0,INDEX('02 Emission rates'!$D$7:$D$15,MATCH(D65,'02 Emission rates'!$A$7:$A$15,1)),NA()) -> 6931.8463 | G65: =E65*F65 -> 26815.394 | H65: =IF(D65>0,INDEX('02 Emission rates'!$E$7:$E$15,MATCH(D65,'02 Emission rates'!$A$7:$A$15,1)),NA()) -> 4.0758788 | I65: =E65*H65 -> 15.767271 | J65: =IF(D65>0,INDEX('02 Emission rates'!$F$7:$F$15,MATCH(D65,'02 Emission rates'!$A$7:$A$15,1)),NA()) -> 62.680628 | K65: =E65*J65 -> 242.47591 | L65: =IF(D65>0,INDEX('02 Emission rates'!$G$7:$G$15,MATCH(D65,'02 Emission rates'!$A$7:$A$15,1)),NA()) -> 2.7514068 | M65: =E65*L65 -> 10.643637
A67: Total / mean | B67: =SUM(B9:B65) -> 4789.25 | C67: =E67/B67*60 -> 2.6488568 | D67: =B67*'01 Traffic inputs'!$B$8/E67 -> 23.557332 | E67: =SUM(E9:E65) -> 211.43396 | F67: =G67/E67 -> 6931.8463 | G67: =SUM(G9:G65) -> 1465627.7 | H67: =I67/E67 -> 4.0758788 | I67: =SUM(I9:I65) -> 861.77919 | J67: =K67/E67 -> 62.680628 | K67: =SUM(K9:K65) -> 13252.813 | L67: =M67/E67 -> 2.7514068 | M67: =SUM(M9:M65) -> 581.74083

Sheet 05 Reconstructed R
A1: R | reconstructed trip speeds
A2: Five-minute emissions are full-link emissions assigned to vehicles counted in that interval, not exhaust physically released during those five minutes. Effective rate = bin emissions / bin vehicle-hours.
A7: Count D | B7: ='03 Recorded O'!B69 -> 4789.25 | D7: P̂ = max(fd × (D/C)^n, D/C). Peak delay = Tf × fp × P̂^s. Mean delay = θ × peak delay. The curve shape reproduces the calibrated mean-to-peak ratio.
A8: D/C (h) | B8: =B7/'01 Traffic inputs'!$B$9 -> 3.1893978
A9: Duration P̂ (h) | B9: =MAX('01 Traffic inputs'!$B$12*B8^'01 Traffic inputs'!$B$13,B8) -> 4.44946
A10: Free time Tf (h) | B10: ='01 Traffic inputs'!$B$8/'01 Traffic inputs'!$B$10 -> 0.016209129
A11: Peak delay (h) | B11: =B10*'01 Traffic inputs'!$B$14*B9^'01 Traffic inputs'!$B$15 -> 0.05733975
A12: Mean delay (h) | B12: ='01 Traffic inputs'!$B$16*B11 -> 0.024933007 | D12: A count-preserving alignment places reconstructed vehicle groups into the observed five-minute count bins. It preserves all episode totals. R, M and A therefore have the same effective speed profile.
A13: Discharge μ (veh/h) | B13: =B7/B9 -> 1076.3666
A14: Wave speed ω (mph) | B14: ='01 Traffic inputs'!$B$9/('01 Traffic inputs'!$B$11-'01 Traffic inputs'!$B$9/'01 Traffic inputs'!$B$10) -> 7.6380685
A15: Queue speed vq (mph) | B15: =B13/('01 Traffic inputs'!$B$11-B13/B14) -> 13.611335
A16: Shape exponent a | B16: =D139 -> 3.3963859
A17: Flat exponent b | B17: ='01 Traffic inputs'!$B$16/(1-'01 Traffic inputs'!$B$16) -> 0.76937715
A18: Vehicle-hours | B18: =SUM(G145:G528) -> 197.03998 | D18: Helper columns X:AE hold cumulative interpolation. The 50-step shape solution and 384-node integration are below the main table. Fixed numerical settings: 2/3 shape threshold, bracket [1,10000], 50 iterations, 1e−10 h tolerance.
A19: Mean trip speed | B19: =B7*'01 Traffic inputs'!$B$8/B18 -> 25.278221
A20: Validity | B20: =IF(AND('01 Traffic inputs'!$B$16>0,'01 Traffic inputs'!$B$16<1,OR('01 Traffic inputs'!$B$16>2/3,'01 Traffic inputs'!$B$16>=EXP(10000*LN(4)+2*GAMMALN(10001)-GAMMALN(20002))),B15>='01 Traffic inputs'!$B$21,B15<'01 Traffic inputs'!$B$10,'01 Traffic inputs'!$B$10<='01 Traffic inputs'!$B$22,MIN(E145:E528)>=0,MIN(F145:F528)>=B10,B11<='01 Traffic inputs'!$B$8/B15-B10+0.0000000001),"VALID","CHECK INPUTS") -> VALID
A23: Clock time | B23: Count / 5 min | C23: Mean trip time (min) | D23: Effective speed (mph) | E23: Vehicle-hours | F23: CO₂ effective rate (g/veh·h) | G23: CO₂ / 5 min (g) | H23: NOₓ effective rate | I23: NOₓ / 5 min (g) | J23: CO effective rate | K23: CO / 5 min (g) | L23: HC effective rate | M23: HC / 5 min (g) | X23: Cumulative count | Y23: Lower index | Z23: Fraction | AA23: Cumulative VHT | AB23: Cumulative CO₂ | AC23: Cumulative NOₓ | AD23: Cumulative CO | AE23: Cumulative HC
A24: ='03 Recorded O'!A11 -> 0.61458333 | B24: ='03 Recorded O'!B11 -> 125.54167 | C24: =E24/B24*60 -> 0.9728915 | D24: =B24*'01 Traffic inputs'!$B$8/E24 -> 64.138704 | E24: =AA24 -> 2.0356403 | F24: =G24/E24 -> 18794.539 | G24: =AB24 -> 38258.921 | H24: =I24/E24 -> 26.733293 | I24: =AC24 -> 54.419369 | J24: =K24/E24 -> 121.2098 | K24: =AD24 -> 246.73955 | L24: =M24/E24 -> 5.099758 | M24: =AE24 -> 10.381273 | X24: =SUM($B$24:B24) -> 125.54167 | Y24: =MIN(MATCH(X24,$R$144:$R$528,1),384) -> 40 | Z24: =(X24-INDEX($R$144:$R$528,Y24))/(INDEX($R$144:$R$528,Y24+1)-INDEX($R$144:$R$528,Y24)) -> 0.54981304 | AA24: =INDEX($S$144:$S$528,Y24)+Z24*(INDEX($S$144:$S$528,Y24+1)-INDEX($S$144:$S$528,Y24)) -> 2.0356403 | AB24: =INDEX($T$144:$T$528,Y24)+Z24*(INDEX($T$144:$T$528,Y24+1)-INDEX($T$144:$T$528,Y24)) -> 38258.921 | AC24: =INDEX($U$144:$U$528,Y24)+Z24*(INDEX($U$144:$U$528,Y24+1)-INDEX($U$144:$U$528,Y24)) -> 54.419369 | AD24: =INDEX($V$144:$V$528,Y24)+Z24*(INDEX($V$144:$V$528,Y24+1)-INDEX($V$144:$V$528,Y24)) -> 246.73955 | AE24: =INDEX($W$144:$W$528,Y24)+Z24*(INDEX($W$144:$W$528,Y24+1)-INDEX($W$144:$W$528,Y24)) -> 10.381273
A25: ='03 Recorded O'!A12 -> 0.61805556 | B25: ='03 Recorded O'!B12 -> 120.22917 | C25: =E25/B25*60 -> 0.97857373 | D25: =B25*'01 Traffic inputs'!$B$8/E25 -> 63.766274 | E25: =AA25-AA24 -> 1.9608851 | F25: =G25/E25 -> 15845.528 | G25: =AB25-AB24 -> 31071.259 | H25: =I25/E25 -> 20.885655 | I25: =AC25-AC24 -> 40.954368 | J25: =K25/E25 -> 98.655406 | K25: =AD25-AD24 -> 193.45191 | L25: =M25/E25 -> 4.4998306 | M25: =AE25-AE24 -> 8.8236506 | X25: =SUM($B$24:B25) -> 245.77083 | Y25: =MIN(MATCH(X25,$R$144:$R$528,1),384) -> 56 | Z25: =(X25-INDEX($R$144:$R$528,Y25))/(INDEX($R$144:$R$528,Y25+1)-INDEX($R$144:$R$528,Y25)) -> 0.65744473 | AA25: =INDEX($S$144:$S$528,Y25)+Z25*(INDEX($S$144:$S$528,Y25+1)-INDEX($S$144:$S$528,Y25)) -> 3.9965254 | AB25: =INDEX($T$144:$T$528,Y25)+Z25*(INDEX($T$144:$T$528,Y25+1)-INDEX($T$144:$T$528,Y25)) -> 69330.18 | AC25: =INDEX($U$144:$U$528,Y25)+Z25*(INDEX($U$144:$U$528,Y25+1)-INDEX($U$144:$U$528,Y25)) -> 95.373737 | AD25: =INDEX($V$144:$V$528,Y25)+Z25*(INDEX($V$144:$V$528,Y25+1)-INDEX($V$144:$V$528,Y25)) -> 440.19146 | AE25: =INDEX($W$144:$W$528,Y25)+Z25*(INDEX($W$144:$W$528,Y25+1)-INDEX($W$144:$W$528,Y25)) -> 19.204924
A26: ='03 Recorded O'!A13 -> 0.62152778 | B26: ='03 Recorded O'!B13 -> 116.20833 | C26: =E26/B26*60 -> 0.99959778 | D26: =B26*'01 Traffic inputs'!$B$8/E26 -> 62.425108 | E26: =AA26-AA25 -> 1.9360265 | F26: =G26/E26 -> 15845.528 | G26: =AB26-AB25 -> 30677.363 | H26: =I26/E26 -> 20.885655 | I26: =AC26-AC25 -> 40.435182 | J26: =K26/E26 -> 98.655406 | K26: =AD26-AD25 -> 190.99948 | L26: =M26/E26 -> 4.4998306 | M26: =AE26-AE25 -> 8.7117914 | X26: =SUM($B$24:B26) -> 361.97917 | Y26: =MIN(MATCH(X26,$R$144:$R$528,1),384) -> 68 | Z26: =(X26-INDEX($R$144:$R$528,Y26))/(INDEX($R$144:$R$528,Y26+1)-INDEX($R$144:$R$528,Y26)) -> 0.84460943 | AA26: =INDEX($S$144:$S$528,Y26)+Z26*(INDEX($S$144:$S$528,Y26+1)-INDEX($S$144:$S$528,Y26)) -> 5.932552 | AB26: =INDEX($T$144:$T$528,Y26)+Z26*(INDEX($T$144:$T$528,Y26+1)-INDEX($T$144:$T$528,Y26)) -> 100007.54 | AC26: =INDEX($U$144:$U$528,Y26)+Z26*(INDEX($U$144:$U$528,Y26+1)-INDEX($U$144:$U$528,Y26)) -> 135.80892 | AD26: =INDEX($V$144:$V$528,Y26)+Z26*(INDEX($V$144:$V$528,Y26+1)-INDEX($V$144:$V$528,Y26)) -> 631.19095 | AE26: =INDEX($W$144:$W$528,Y26)+Z26*(INDEX($W$144:$W$528,Y26+1)-INDEX($W$144:$W$528,Y26)) -> 27.916715
A27: ='03 Recorded O'!A14 -> 0.625 | B27: ='03 Recorded O'!B14 -> 109.89583 | C27: =E27/B27*60 -> 1.0433026 | D27: =B27*'01 Traffic inputs'!$B$8/E27 -> 59.810067 | E27: =AA27-AA26 -> 1.9109102 | F27: =G27/E27 -> 15845.528 | G27: =AB27-AB26 -> 30279.381 | H27: =I27/E27 -> 20.885655 | I27: =AC27-AC26 -> 39.91061 | J27: =K27/E27 -> 98.655406 | K27: =AD27-AD26 -> 188.52162 | L27: =M27/E27 -> 4.4998306 | M27: =AE27-AE26 -> 8.5987722 | X27: =SUM($B$24:B27) -> 471.875 | Y27: =MIN(MATCH(X27,$R$144:$R$528,1),384) -> 78 | Z27: =(X27-INDEX($R$144:$R$528,Y27))/(INDEX($R$144:$R$528,Y27+1)-INDEX($R$144:$R$528,Y27)) -> 0.74914436 | AA27: =INDEX($S$144:$S$528,Y27)+Z27*(INDEX($S$144:$S$528,Y27+1)-INDEX($S$144:$S$528,Y27)) -> 7.8434622 | AB27: =INDEX($T$144:$T$528,Y27)+Z27*(INDEX($T$144:$T$528,Y27+1)-INDEX($T$144:$T$528,Y27)) -> 130286.92 | AC27: =INDEX($U$144:$U$528,Y27)+Z27*(INDEX($U$144:$U$528,Y27+1)-INDEX($U$144:$U$528,Y27)) -> 175.71953 | AD27: =INDEX($V$144:$V$528,Y27)+Z27*(INDEX($V$144:$V$528,Y27+1)-INDEX($V$144:$V$528,Y27)) -> 819.71257 | AE27: =INDEX($W$144:$W$528,Y27)+Z27*(INDEX($W$144:$W$528,Y27+1)-INDEX($W$144:$W$528,Y27)) -> 36.515487
A28: ='03 Recorded O'!A15 -> 0.62847222 | B28: ='03 Recorded O'!B15 -> 106.89583 | C28: =E28/B28*60 -> 1.1131657 | D28: =B28*'01 Traffic inputs'!$B$8/E28 -> 56.056346 | E28: =AA28-AA27 -> 1.9832129 | F28: =G28/E28 -> 15845.528 | G28: =AB28-AB27 -> 31425.055 | H28: =I28/E28 -> 20.885655 | I28: =AC28-AC27 -> 41.420699 | J28: =K28/E28 -> 98.655406 | K28: =AD28-AD27 -> 195.65467 | L28: =M28/E28 -> 4.4998306 | M28: =AE28-AE27 -> 8.9241219 | X28: =SUM($B$24:B28) -> 578.77083 | Y28: =MIN(MATCH(X28,$R$144:$R$528,1),384) -> 87 | Z28: =(X28-INDEX($R$144:$R$528,Y28))/(INDEX($R$144:$R$528,Y28+1)-INDEX($R$144:$R$528,Y28)) -> 0.3964635 | AA28: =INDEX($S$144:$S$528,Y28)+Z28*(INDEX($S$144:$S$528,Y28+1)-INDEX($S$144:$S$528,Y28)) -> 9.826675 | AB28: =INDEX($T$144:$T$528,Y28)+Z28*(INDEX($T$144:$T$528,Y28+1)-INDEX($T$144:$T$528,Y28)) -> 161711.98 | AC28: =INDEX($U$144:$U$528,Y28)+Z28*(INDEX($U$144:$U$528,Y28+1)-INDEX($U$144:$U$528,Y28)) -> 217.14023 | AD28: =INDEX($V$144:$V$528,Y28)+Z28*(INDEX($V$144:$V$528,Y28+1)-INDEX($V$144:$V$528,Y28)) -> 1015.3672 | AE28: =INDEX($W$144:$W$528,Y28)+Z28*(INDEX($W$144:$W$528,Y28+1)-INDEX($W$144:$W$528,Y28)) -> 45.439609
A29: ='03 Recorded O'!A16 -> 0.63194444 | B29: ='03 Recorded O'!B16 -> 104.52083 | C29: =E29/B29*60 -> 1.2108971 | D29: =B29*'01 Traffic inputs'!$B$8/E29 -> 51.532043 | E29: =AA29-AA28 -> 2.1093995 | F29: =G29/E29 -> 15309.97 | G29: =AB29-AB28 -> 32294.843 | H29: =I29/E29 -> 20.072715 | I29: =AC29-AC28 -> 42.341376 | J29: =K29/E29 -> 104.70454 | K29: =AD29-AD28 -> 220.86371 | L29: =M29/E29 -> 4.5553829 | M29: =AE29-AE28 -> 9.6091225 | X29: =SUM($B$24:B29) -> 683.29167 | Y29: =MIN(MATCH(X29,$R$144:$R$528,1),384) -> 95 | Z29: =(X29-INDEX($R$144:$R$528,Y29))/(INDEX($R$144:$R$528,Y29+1)-INDEX($R$144:$R$528,Y29)) -> 0.17110469 | AA29: =INDEX($S$144:$S$528,Y29)+Z29*(INDEX($S$144:$S$528,Y29+1)-INDEX($S$144:$S$528,Y29)) -> 11.936075 | AB29: =INDEX($T$144:$T$528,Y29)+Z29*(INDEX($T$144:$T$528,Y29+1)-INDEX($T$144:$T$528,Y29)) -> 194006.82 | AC29: =INDEX($U$144:$U$528,Y29)+Z29*(INDEX($U$144:$U$528,Y29+1)-INDEX($U$144:$U$528,Y29)) -> 259.4816 | AD29: =INDEX($V$144:$V$528,Y29)+Z29*(INDEX($V$144:$V$528,Y29+1)-INDEX($V$144:$V$528,Y29)) -> 1236.2309 | AE29: =INDEX($W$144:$W$528,Y29)+Z29*(INDEX($W$144:$W$528,Y29+1)-INDEX($W$144:$W$528,Y29)) -> 55.048732
A30: ='03 Recorded O'!A17 -> 0.63541667 | B30: ='03 Recorded O'!B17 -> 102.27083 | C30: =E30/B30*60 -> 1.3364204 | D30: =B30*'01 Traffic inputs'!$B$8/E30 -> 46.691896 | E30: =AA30-AA29 -> 2.2779471 | F30: =G30/E30 -> 10788.901 | G30: =AB30-AB29 -> 24576.544 | H30: =I30/E30 -> 11.752532 | I30: =AC30-AC29 -> 26.771646 | J30: =K30/E30 -> 108.46456 | K30: =AD30-AD29 -> 247.07652 | L30: =M30/E30 -> 4.0781138 | M30: =AE30-AE29 -> 9.2897273 | X30: =SUM($B$24:B30) -> 785.5625 | Y30: =MIN(MATCH(X30,$R$144:$R$528,1),384) -> 102 | Z30: =(X30-INDEX($R$144:$R$528,Y30))/(INDEX($R$144:$R$528,Y30+1)-INDEX($R$144:$R$528,Y30)) -> 0.27794911 | AA30: =INDEX($S$144:$S$528,Y30)+Z30*(INDEX($S$144:$S$528,Y30+1)-INDEX($S$144:$S$528,Y30)) -> 14.214022 | AB30: =INDEX($T$144:$T$528,Y30)+Z30*(INDEX($T$144:$T$528,Y30+1)-INDEX($T$144:$T$528,Y30)) -> 218583.37 | AC30: =INDEX($U$144:$U$528,Y30)+Z30*(INDEX($U$144:$U$528,Y30+1)-INDEX($U$144:$U$528,Y30)) -> 286.25325 | AD30: =INDEX($V$144:$V$528,Y30)+Z30*(INDEX($V$144:$V$528,Y30+1)-INDEX($V$144:$V$528,Y30)) -> 1483.3075 | AE30: =INDEX($W$144:$W$528,Y30)+Z30*(INDEX($W$144:$W$528,Y30+1)-INDEX($W$144:$W$528,Y30)) -> 64.338459
A31: ='03 Recorded O'!A18 -> 0.63888889 | B31: ='03 Recorded O'!B18 -> 102.875 | C31: =E31/B31*60 -> 1.4888927 | D31: =B31*'01 Traffic inputs'!$B$8/E31 -> 41.91034 | E31: =AA31-AA30 -> 2.5528307 | F31: =G31/E31 -> 9725.595 | G31: =AB31-AB30 -> 24827.797 | H31: =I31/E31 -> 9.2521191 | I31: =AC31-AC30 -> 23.619093 | J31: =K31/E31 -> 91.705804 | K31: =AD31-AD30 -> 234.10939 | L31: =M31/E31 -> 3.6129594 | M31: =AE31-AE30 -> 9.2232734 | X31: =SUM($B$24:B31) -> 888.4375 | Y31: =MIN(MATCH(X31,$R$144:$R$528,1),384) -> 109 | Z31: =(X31-INDEX($R$144:$R$528,Y31))/(INDEX($R$144:$R$528,Y31+1)-INDEX($R$144:$R$528,Y31)) -> 0.032170791 | AA31: =INDEX($S$144:$S$528,Y31)+Z31*(INDEX($S$144:$S$528,Y31+1)-INDEX($S$144:$S$528,Y31)) -> 16.766852 | AB31: =INDEX($T$144:$T$528,Y31)+Z31*(INDEX($T$144:$T$528,Y31+1)-INDEX($T$144:$T$528,Y31)) -> 243411.16 | AC31: =INDEX($U$144:$U$528,Y31)+Z31*(INDEX($U$144:$U$528,Y31+1)-INDEX($U$144:$U$528,Y31)) -> 309.87234 | AD31: =INDEX($V$144:$V$528,Y31)+Z31*(INDEX($V$144:$V$528,Y31+1)-INDEX($V$144:$V$528,Y31)) -> 1717.4169 | AE31: =INDEX($W$144:$W$528,Y31)+Z31*(INDEX($W$144:$W$528,Y31+1)-INDEX($W$144:$W$528,Y31)) -> 73.561732
A32: ='03 Recorded O'!A19 -> 0.64236111 | B32: ='03 Recorded O'!B19 -> 99.375 | C32: =E32/B32*60 -> 1.6661587 | D32: =B32*'01 Traffic inputs'!$B$8/E32 -> 37.451415 | E32: =AA32-AA31 -> 2.7595753 | F32: =G32/E32 -> 9725.595 | G32: =AB32-AB31 -> 26838.512 | H32: =I32/E32 -> 9.2521191 | I32: =AC32-AC31 -> 25.53192 | J32: =K32/E32 -> 91.705804 | K32: =AD32-AD31 -> 253.06907 | L32: =M32/E32 -> 3.6129594 | M32: =AE32-AE31 -> 9.9702335 | X32: =SUM($B$24:B32) -> 987.8125 | Y32: =MIN(MATCH(X32,$R$144:$R$528,1),384) -> 115 | Z32: =(X32-INDEX($R$144:$R$528,Y32))/(INDEX($R$144:$R$528,Y32+1)-INDEX($R$144:$R$528,Y32)) -> 0.24966281 | AA32: =INDEX($S$144:$S$528,Y32)+Z32*(INDEX($S$144:$S$528,Y32+1)-INDEX($S$144:$S$528,Y32)) -> 19.526428 | AB32: =INDEX($T$144:$T$528,Y32)+Z32*(INDEX($T$144:$T$528,Y32+1)-INDEX($T$144:$T$528,Y32)) -> 270249.67 | AC32: =INDEX($U$144:$U$528,Y32)+Z32*(INDEX($U$144:$U$528,Y32+1)-INDEX($U$144:$U$528,Y32)) -> 335.40426 | AD32: =INDEX($V$144:$V$528,Y32)+Z32*(INDEX($V$144:$V$528,Y32+1)-INDEX($V$144:$V$528,Y32)) -> 1970.4859 | AE32: =INDEX($W$144:$W$528,Y32)+Z32*(INDEX($W$144:$W$528,Y32+1)-INDEX($W$144:$W$528,Y32)) -> 83.531966
A33: ='03 Recorded O'!A20 -> 0.64583333 | B33: ='03 Recorded O'!B20 -> 99.3125 | C33: =E33/B33*60 -> 1.8615828 | D33: =B33*'01 Traffic inputs'!$B$8/E33 -> 33.519863 | E33: =AA33-AA32 -> 3.0813073 | F33: =G33/E33 -> 8681.817 | G33: =AB33-AB32 -> 26751.347 | H33: =I33/E33 -> 7.4786198 | I33: =AC33-AC32 -> 23.043926 | J33: =K33/E33 -> 79.792462 | K33: =AD33-AD32 -> 245.8651 | L33: =M33/E33 -> 3.3060372 | M33: =AE33-AE32 -> 10.186917 | X33: =SUM($B$24:B33) -> 1087.125 | Y33: =MIN(MATCH(X33,$R$144:$R$528,1),384) -> 121 | Z33: =(X33-INDEX($R$144:$R$528,Y33))/(INDEX($R$144:$R$528,Y33+1)-INDEX($R$144:$R$528,Y33)) -> 0.21675548 | AA33: =INDEX($S$144:$S$528,Y33)+Z33*(INDEX($S$144:$S$528,Y33+1)-INDEX($S$144:$S$528,Y33)) -> 22.607735 | AB33: =INDEX($T$144:$T$528,Y33)+Z33*(INDEX($T$144:$T$528,Y33+1)-INDEX($T$144:$T$528,Y33)) -> 297001.02 | AC33: =INDEX($U$144:$U$528,Y33)+Z33*(INDEX($U$144:$U$528,Y33+1)-INDEX($U$144:$U$528,Y33)) -> 358.44819 | AD33: =INDEX($V$144:$V$528,Y33)+Z33*(INDEX($V$144:$V$528,Y33+1)-INDEX($V$144:$V$528,Y33)) -> 2216.351 | AE33: =INDEX($W$144:$W$528,Y33)+Z33*(INDEX($W$144:$W$528,Y33+1)-INDEX($W$144:$W$528,Y33)) -> 93.718883
A34: ='03 Recorded O'!A21 -> 0.64930556 | B34: ='03 Recorded O'!B21 -> 94.520833 | C34: =E34/B34*60 -> 2.0706353 | D34: =B34*'01 Traffic inputs'!$B$8/E34 -> 30.135678 | E34: =AA34-AA33 -> 3.2619696 | F34: =G34/E34 -> 7854.4376 | G34: =AB34-AB33 -> 25620.937 | H34: =I34/E34 -> 6.0728067 | I34: =AC34-AC33 -> 19.809311 | J34: =K34/E34 -> 70.349022 | K34: =AD34-AD33 -> 229.47637 | L34: =M34/E34 -> 3.0627468 | M34: =AE34-AE33 -> 9.990587 | X34: =SUM($B$24:B34) -> 1181.6458 | Y34: =MIN(MATCH(X34,$R$144:$R$528,1),384) -> 126 | Z34: =(X34-INDEX($R$144:$R$528,Y34))/(INDEX($R$144:$R$528,Y34+1)-INDEX($R$144:$R$528,Y34)) -> 0.70466013 | AA34: =INDEX($S$144:$S$528,Y34)+Z34*(INDEX($S$144:$S$528,Y34+1)-INDEX($S$144:$S$528,Y34)) -> 25.869705 | AB34: =INDEX($T$144:$T$528,Y34)+Z34*(INDEX($T$144:$T$528,Y34+1)-INDEX($T$144:$T$528,Y34)) -> 322621.96 | AC34: =INDEX($U$144:$U$528,Y34)+Z34*(INDEX($U$144:$U$528,Y34+1)-INDEX($U$144:$U$528,Y34)) -> 378.2575 | AD34: =INDEX($V$144:$V$528,Y34)+Z34*(INDEX($V$144:$V$528,Y34+1)-INDEX($V$144:$V$528,Y34)) -> 2445.8274 | AE34: =INDEX($W$144:$W$528,Y34)+Z34*(INDEX($W$144:$W$528,Y34+1)-INDEX($W$144:$W$528,Y34)) -> 103.70947
A35: ='03 Recorded O'!A22 -> 0.65277778 | B35: ='03 Recorded O'!B22 -> 91.5625 | C35: =E35/B35*60 -> 2.2837152 | D35: =B35*'01 Traffic inputs'!$B$8/E35 -> 27.323897 | E35: =AA35-AA34 -> 3.4850446 | F35: =G35/E35 -> 7854.4376 | G35: =AB35-AB34 -> 27373.065 | H35: =I35/E35 -> 6.0728067 | I35: =AC35-AC34 -> 21.164002 | J35: =K35/E35 -> 70.349022 | K35: =AD35-AD34 -> 245.16948 | L35: =M35/E35 -> 3.0627468 | M35: =AE35-AE34 -> 10.673809 | X35: =SUM($B$24:B35) -> 1273.2083 | Y35: =MIN(MATCH(X35,$R$144:$R$528,1),384) -> 131 | Z35: =(X35-INDEX($R$144:$R$528,Y35))/(INDEX($R$144:$R$528,Y35+1)-INDEX($R$144:$R$528,Y35)) -> 0.87207631 | AA35: =INDEX($S$144:$S$528,Y35)+Z35*(INDEX($S$144:$S$528,Y35+1)-INDEX($S$144:$S$528,Y35)) -> 29.354749 | AB35: =INDEX($T$144:$T$528,Y35)+Z35*(INDEX($T$144:$T$528,Y35+1)-INDEX($T$144:$T$528,Y35)) -> 349995.02 | AC35: =INDEX($U$144:$U$528,Y35)+Z35*(INDEX($U$144:$U$528,Y35+1)-INDEX($U$144:$U$528,Y35)) -> 399.4215 | AD35: =INDEX($V$144:$V$528,Y35)+Z35*(INDEX($V$144:$V$528,Y35+1)-INDEX($V$144:$V$528,Y35)) -> 2690.9969 | AE35: =INDEX($W$144:$W$528,Y35)+Z35*(INDEX($W$144:$W$528,Y35+1)-INDEX($W$144:$W$528,Y35)) -> 114.38328
A36: ='03 Recorded O'!A23 -> 0.65625 | B36: ='03 Recorded O'!B23 -> 89.708333 | C36: =E36/B36*60 -> 2.5010491 | D36: =B36*'01 Traffic inputs'!$B$8/E36 -> 24.94953 | E36: =AA36-AA35 -> 3.7394158 | F36: =G36/E36 -> 7316.4693 | G36: =AB36-AB35 -> 27359.321 | H36: =I36/E36 -> 4.9083864 | I36: =AC36-AC35 -> 18.354498 | J36: =K36/E36 -> 65.877537 | K36: =AD36-AD35 -> 246.3435 | L36: =M36/E36 -> 2.8812026 | M36: =AE36-AE35 -> 10.774015 | X36: =SUM($B$24:B36) -> 1362.9167 | Y36: =MIN(MATCH(X36,$R$144:$R$528,1),384) -> 136 | Z36: =(X36-INDEX($R$144:$R$528,Y36))/(INDEX($R$144:$R$528,Y36+1)-INDEX($R$144:$R$528,Y36)) -> 0.81467223 | AA36: =INDEX($S$144:$S$528,Y36)+Z36*(INDEX($S$144:$S$528,Y36+1)-INDEX($S$144:$S$528,Y36)) -> 33.094165 | AB36: =INDEX($T$144:$T$528,Y36)+Z36*(INDEX($T$144:$T$528,Y36+1)-INDEX($T$144:$T$528,Y36)) -> 377354.34 | AC36: =INDEX($U$144:$U$528,Y36)+Z36*(INDEX($U$144:$U$528,Y36+1)-INDEX($U$144:$U$528,Y36)) -> 417.776 | AD36: =INDEX($V$144:$V$528,Y36)+Z36*(INDEX($V$144:$V$528,Y36+1)-INDEX($V$144:$V$528,Y36)) -> 2937.3404 | AE36: =INDEX($W$144:$W$528,Y36)+Z36*(INDEX($W$144:$W$528,Y36+1)-INDEX($W$144:$W$528,Y36)) -> 125.15729
... A80: ='03 Recorded O'!A67 -> 0.80902778 | B80: ='03 Recorded O'!B67 -> 87.625 | C80: =E80/B80*60 -> 0.97265102 | D80: =B80*'01 Traffic inputs'!$B$8/E80 -> 64.154562 | E80: =AA80-AA79 -> 1.4204758 | F80: =G80/E80 -> 20071.08 | G80: =AB80-AB79 -> 28510.482 | H80: =I80/E80 -> 29.264566 | I80: =AC80-AC79 -> 41.569606 | J80: =K80/E80 -> 130.97294 | K80: =AD80-AD79 -> 186.04388 | L80: =M80/E80 -> 5.3594492 | M80: =AE80-AE79 -> 7.6129677 | X80: =SUM($B$24:B80) -> 4789.25 | Y80: =MIN(MATCH(X80,$R$144:$R$528,1),384) -> 384 | Z80: =(X80-INDEX($R$144:$R$528,Y80))/(INDEX($R$144:$R$528,Y80+1)-INDEX($R$144:$R$528,Y80)) -> 1 | AA80: =INDEX($S$144:$S$528,Y80)+Z80*(INDEX($S$144:$S$528,Y80+1)-INDEX($S$144:$S$528,Y80)) -> 197.03998 | AB80: =INDEX($T$144:$T$528,Y80)+Z80*(INDEX($T$144:$T$528,Y80+1)-INDEX($T$144:$T$528,Y80)) -> 1657640 | AC80: =INDEX($U$144:$U$528,Y80)+Z80*(INDEX($U$144:$U$528,Y80+1)-INDEX($U$144:$U$528,Y80)) -> 1360.9023 | AD80: =INDEX($V$144:$V$528,Y80)+Z80*(INDEX($V$144:$V$528,Y80+1)-INDEX($V$144:$V$528,Y80)) -> 14045.025 | AE80: =INDEX($W$144:$W$528,Y80)+Z80*(INDEX($W$144:$W$528,Y80+1)-INDEX($W$144:$W$528,Y80)) -> 609.21551
A82: Total / mean | B82: =SUM(B24:B80) -> 4789.25 | C82: =E82/B82*60 -> 2.4685282 | D82: =B82*'01 Traffic inputs'!$B$8/E82 -> 25.278221 | E82: =SUM(E24:E80) -> 197.03998 | F82: =G82/E82 -> 8412.709 | G82: =SUM(G24:G80) -> 1657640 | H82: =I82/E82 -> 6.9067322 | I82: =SUM(I24:I80) -> 1360.9023 | J82: =K82/E82 -> 71.280077 | K82: =SUM(K24:K80) -> 14045.025 | L82: =M82/E82 -> 3.0918371 | M82: =SUM(M24:M80) -> 609.21551
A89: Iteration | B89: Lower a | C89: Upper a | D89: Midpoint a | E89: Mean shape
A90: =1 -> 1 | B90: =1 -> 1 | C90: =10000 -> 10000 | D90: =(B90+C90)/2 -> 5000.5 | E90: =EXP(D90*LN(4)+2*GAMMALN(D90+1)-GAMMALN(2*D90+2)) -> 0.012531575
A91: =2 -> 2 | B91: =IF(E90>'01 Traffic inputs'!$B$16,D90,B90) -> 1 | C91: =IF(E90>'01 Traffic inputs'!$B$16,C90,D90) -> 5000.5 | D91: =(B91+C91)/2 -> 2500.75 | E91: =EXP(D91*LN(4)+2*GAMMALN(D91+1)-GAMMALN(2*D91+2)) -> 0.017719223
A92: =3 -> 3 | B92: =IF(E91>'01 Traffic inputs'!$B$16,D91,B91) -> 1 | C92: =IF(E91>'01 Traffic inputs'!$B$16,C91,D91) -> 2500.75 | D92: =(B92+C92)/2 -> 1250.875 | E92: =EXP(D92*LN(4)+2*GAMMALN(D92+1)-GAMMALN(2*D92+2)) -> 0.025050005
A93: =4 -> 4 | B93: =IF(E92>'01 Traffic inputs'!$B$16,D92,B92) -> 1 | C93: =IF(E92>'01 Traffic inputs'!$B$16,C92,D92) -> 1250.875 | D93: =(B93+C93)/2 -> 625.9375 | E93: =EXP(D93*LN(4)+2*GAMMALN(D93+1)-GAMMALN(2*D93+2)) -> 0.035401316
A94: =5 -> 5 | B94: =IF(E93>'01 Traffic inputs'!$B$16,D93,B93) -> 1 | C94: =IF(E93>'01 Traffic inputs'!$B$16,C93,D93) -> 625.9375 | D94: =(B94+C94)/2 -> 313.46875 | E94: =EXP(D94*LN(4)+2*GAMMALN(D94+1)-GAMMALN(2*D94+2)) -> 0.049995259
A95: =6 -> 6 | B95: =IF(E94>'01 Traffic inputs'!$B$16,D94,B94) -> 1 | C95: =IF(E94>'01 Traffic inputs'!$B$16,C94,D94) -> 313.46875 | D95: =(B95+C95)/2 -> 157.23438 | E95: =EXP(D95*LN(4)+2*GAMMALN(D95+1)-GAMMALN(2*D95+2)) -> 0.070507871
A96: =7 -> 7 | B96: =IF(E95>'01 Traffic inputs'!$B$16,D95,B95) -> 1 | C96: =IF(E95>'01 Traffic inputs'!$B$16,C95,D95) -> 157.23438 | D96: =(B96+C96)/2 -> 79.117188 | E96: =EXP(D96*LN(4)+2*GAMMALN(D96+1)-GAMMALN(2*D96+2)) -> 0.099165289
...

Sheet 06 Two-speed M
A1: M | two speeds with lookup emission rates
A2: Free and queue times are per-vehicle bin averages. Free + queue emissions = assigned bin emissions. R/M/A share total travel time. All rates are g/(veh·h); all emission totals below are grams.
A6: Pollutant | B6: Free-flow rate | C6: Queue rate
A8: CO₂ | B8: =IF('01 Traffic inputs'!$B$10>0,INDEX('02 Emission rates'!$D$7:$D$15,MATCH('01 Traffic inputs'!$B$10,'02 Emission rates'!$A$7:$A$15,1)),NA()) -> 20615.635 | C8: =IF('05 Reconstructed R'!$B$15>0,INDEX('02 Emission rates'!$D$7:$D$15,MATCH('05 Reconstructed R'!$B$15,'02 Emission rates'!$A$7:$A$15,1)),NA()) -> 6931.8463
A9: NOₓ | B9: =IF('01 Traffic inputs'!$B$10>0,INDEX('02 Emission rates'!$E$7:$E$15,MATCH('01 Traffic inputs'!$B$10,'02 Emission rates'!$A$7:$A$15,1)),NA()) -> 30.344373 | C9: =IF('05 Reconstructed R'!$B$15>0,INDEX('02 Emission rates'!$E$7:$E$15,MATCH('05 Reconstructed R'!$B$15,'02 Emission rates'!$A$7:$A$15,1)),NA()) -> 4.0758788
A10: CO | B10: =IF('01 Traffic inputs'!$B$10>0,INDEX('02 Emission rates'!$F$7:$F$15,MATCH('01 Traffic inputs'!$B$10,'02 Emission rates'!$A$7:$A$15,1)),NA()) -> 135.13776 | C10: =IF('05 Reconstructed R'!$B$15>0,INDEX('02 Emission rates'!$F$7:$F$15,MATCH('05 Reconstructed R'!$B$15,'02 Emission rates'!$A$7:$A$15,1)),NA()) -> 62.680628
A11: HC | B11: =IF('01 Traffic inputs'!$B$10>0,INDEX('02 Emission rates'!$G$7:$G$15,MATCH('01 Traffic inputs'!$B$10,'02 Emission rates'!$A$7:$A$15,1)),NA()) -> 5.47023 | C11: =IF('05 Reconstructed R'!$B$15>0,INDEX('02 Emission rates'!$G$7:$G$15,MATCH('05 Reconstructed R'!$B$15,'02 Emission rates'!$A$7:$A$15,1)),NA()) -> 2.7514068
A13: Time allocation: Tq = vf × delay / (vf − vq); Tfree = L/vf − vq × delay / (vf − vq). At each bin, delay = reconstructed mean trip time − L/vf.
A18: Emissions: Ef = count × Tfree × r(vf); Eq = count × Tq × r(vq). Effective rate = (Ef + Eq) / vehicle-hours. Times are shown in minutes and converted to hours in the formulas.
A23: Clock time | B23: Count / 5 min | C23: Free time (min) | D23: Queue time (min) | E23: Effective speed (mph) | F23: Vehicle-hours | G23: CO₂ free (g) | H23: CO₂ queue (g) | I23: CO₂ eff. rate | J23: CO₂ / 5 min (g) | K23: NOₓ free (g) | L23: NOₓ queue (g) | M23: NOₓ eff. rate | N23: NOₓ / 5 min (g) | O23: CO free (g) | P23: CO queue (g) | Q23: CO eff. rate | R23: CO / 5 min (g) | S23: HC free (g) | T23: HC queue (g) | U23: HC eff. rate | V23: HC / 5 min (g)
A24: ='03 Recorded O'!A11 -> 0.61458333 | B24: ='03 Recorded O'!B11 -> 125.54167 | C24: =('05 Reconstructed R'!$B$10-'05 Reconstructed R'!$B$15*('05 Reconstructed R'!E24/B24-'05 Reconstructed R'!$B$10)/('01 Traffic inputs'!$B$10-'05 Reconstructed R'!$B$15))*60 -> 0.97245517 | D24: ='01 Traffic inputs'!$B$10*('05 Reconstructed R'!E24/B24-'05 Reconstructed R'!$B$10)/('01 Traffic inputs'!$B$10-'05 Reconstructed R'!$B$15)*60 -> 0.00043633018 | E24: ='05 Reconstructed R'!D24 -> 64.138704 | F24: =B24*(C24+D24)/60 -> 2.0356403 | G24: =B24*C24/60*$B$8 -> 41947.198 | H24: =B24*D24/60*$C$8 -> 6.3285005 | I24: =J24/F24 -> 20609.498 | J24: =G24+H24 -> 41953.526 | K24: =B24*C24/60*$B$9 -> 61.742527 | L24: =B24*D24/60*$C$9 -> 0.0037211156 | M24: =N24/F24 -> 30.332592 | N24: =K24+L24 -> 61.746248 | O24: =B24*C24/60*$B$10 -> 274.96851 | P24: =B24*D24/60*$C$10 -> 0.057224925 | Q24: =R24/F24 -> 135.10527 | R24: =O24+P24 -> 275.02573 | S24: =B24*C24/60*$B$11 -> 11.130427 | T24: =B24*D24/60*$C$11 -> 0.0025119252 | U24: =V24/F24 -> 5.4690107 | V24: =S24+T24 -> 11.132939
A25: ='03 Recorded O'!A12 -> 0.61805556 | B25: ='03 Recorded O'!B12 -> 120.22917 | C25: =('05 Reconstructed R'!$B$10-'05 Reconstructed R'!$B$15*('05 Reconstructed R'!E25/B25-'05 Reconstructed R'!$B$10)/('01 Traffic inputs'!$B$10-'05 Reconstructed R'!$B$15))*60 -> 0.97092515 | D25: ='01 Traffic inputs'!$B$10*('05 Reconstructed R'!E25/B25-'05 Reconstructed R'!$B$10)/('01 Traffic inputs'!$B$10-'05 Reconstructed R'!$B$15)*60 -> 0.0076485746 | E25: ='05 Reconstructed R'!D25 -> 63.766274 | F25: =B25*(C25+D25)/60 -> 1.9608851 | G25: =B25*C25/60*$B$8 -> 40108.928 | H25: =B25*D25/60*$C$8 -> 106.23999 | I25: =J25/F25 -> 20508.682 | J25: =G25+H25 -> 40215.168 | K25: =B25*C25/60*$B$9 -> 59.036759 | L25: =B25*D25/60*$C$9 -> 0.062468396 | M25: =N25/F25 -> 30.139057 | N25: =K25+L25 -> 59.099228 | O25: =B25*C25/60*$B$10 -> 262.91845 | P25: =B25*D25/60*$C$10 -> 0.96066603 | Q25: =R25/F25 -> 134.57144 | R25: =O25+P25 -> 263.87912 | S25: =B25*C25/60*$B$11 -> 10.642654 | T25: =B25*D25/60*$C$11 -> 0.042169058 | U25: =V25/F25 -> 5.4489796 | V25: =S25+T25 -> 10.684823
A26: ='03 Recorded O'!A13 -> 0.62152778 | B26: ='03 Recorded O'!B13 -> 116.20833 | C26: =('05 Reconstructed R'!$B$10-'05 Reconstructed R'!$B$15*('05 Reconstructed R'!E26/B26-'05 Reconstructed R'!$B$10)/('01 Traffic inputs'!$B$10-'05 Reconstructed R'!$B$15))*60 -> 0.96526412 | D26: ='01 Traffic inputs'!$B$10*('05 Reconstructed R'!E26/B26-'05 Reconstructed R'!$B$10)/('01 Traffic inputs'!$B$10-'05 Reconstructed R'!$B$15)*60 -> 0.034333666 | E26: ='05 Reconstructed R'!D26 -> 62.425108 | F26: =B26*(C26+D26)/60 -> 1.9360265 | G26: =B26*C26/60*$B$8 -> 38541.526 | H26: =B26*D26/60*$C$8 -> 460.95139 | I26: =J26/F26 -> 20145.632 | J26: =G26+H26 -> 39002.477 | K26: =B26*C26/60*$B$9 -> 56.729683 | L26: =B26*D26/60*$C$9 -> 0.27103631 | M26: =N26/F26 -> 29.442117 | N26: =K26+L26 -> 57.000719 | O26: =B26*C26/60*$B$10 -> 252.64395 | P26: =B26*D26/60*$C$10 -> 4.1681136 | Q26: =R26/F26 -> 132.64904 | R26: =O26+P26 -> 256.81207 | S26: =B26*C26/60*$B$11 -> 10.226753 | T26: =B26*D26/60*$C$11 -> 0.18296205 | U26: =V26/F26 -> 5.3768453 | V26: =S26+T26 -> 10.409715
A27: ='03 Recorded O'!A14 -> 0.625 | B27: ='03 Recorded O'!B14 -> 109.89583 | C27: =('05 Reconstructed R'!$B$10-'05 Reconstructed R'!$B$15*('05 Reconstructed R'!E27/B27-'05 Reconstructed R'!$B$10)/('01 Traffic inputs'!$B$10-'05 Reconstructed R'!$B$15))*60 -> 0.95349595 | D27: ='01 Traffic inputs'!$B$10*('05 Reconstructed R'!E27/B27-'05 Reconstructed R'!$B$10)/('01 Traffic inputs'!$B$10-'05 Reconstructed R'!$B$15)*60 -> 0.089806677 | E27: ='05 Reconstructed R'!D27 -> 59.810067 | F27: =B27*(C27+D27)/60 -> 1.9109102 | G27: =B27*C27/60*$B$8 -> 36003.569 | H27: =B27*D27/60*$C$8 -> 1140.217 | I27: =J27/F27 -> 19437.745 | J27: =G27+H27 -> 37143.786 | K27: =B27*C27/60*$B$9 -> 52.994037 | L27: =B27*D27/60*$C$9 -> 0.67043993 | M27: =N27/F27 -> 28.083202 | N27: =K27+L27 -> 53.664476 | O27: =B27*C27/60*$B$10 -> 236.00737 | P27: =B27*D27/60*$C$10 -> 10.310315 | Q27: =R27/F27 -> 128.90071 | R27: =O27+P27 -> 246.31768 | S27: =B27*C27/60*$B$11 -> 9.5533221 | T27: =B27*D27/60*$C$11 -> 0.45257797 | U27: =V27/F27 -> 5.2361959 | V27: =S27+T27 -> 10.0059
A28: ='03 Recorded O'!A15 -> 0.62847222 | B28: ='03 Recorded O'!B15 -> 106.89583 | C28: =('05 Reconstructed R'!$B$10-'05 Reconstructed R'!$B$15*('05 Reconstructed R'!E28/B28-'05 Reconstructed R'!$B$10)/('01 Traffic inputs'!$B$10-'05 Reconstructed R'!$B$15))*60 -> 0.93468431 | D28: ='01 Traffic inputs'!$B$10*('05 Reconstructed R'!E28/B28-'05 Reconstructed R'!$B$10)/('01 Traffic inputs'!$B$10-'05 Reconstructed R'!$B$15)*60 -> 0.17848137 | E28: ='05 Reconstructed R'!D28 -> 56.056346 | F28: =B28*(C28+D28)/60 -> 1.9832129 | G28: =B28*C28/60*$B$8 -> 34329.794 | H28: =B28*D28/60*$C$8 -> 2204.2017 | I28: =J28/F28 -> 18421.621 | J28: =G28+H28 -> 36533.996 | K28: =B28*C28/60*$B$9 -> 50.53039 | L28: =B28*D28/60*$C$9 -> 1.2960557 | M28: =N28/F28 -> 26.132568 | N28: =K28+L28 -> 51.826446 | O28: =B28*C28/60*$B$10 -> 225.03559 | P28: =B28*D28/60*$C$10 -> 19.931305 | Q28: =R28/F28 -> 123.52022 | R28: =O28+P28 -> 244.96689 | S28: =B28*C28/60*$B$11 -> 9.1091965 | T28: =B28*D28/60*$C$11 -> 0.87489758 | U28: =V28/F28 -> 5.0343028 | V28: =S28+T28 -> 9.9840941
A29: ='03 Recorded O'!A16 -> 0.63194444 | B29: ='03 Recorded O'!B16 -> 104.52083 | C29: =('05 Reconstructed R'!$B$10-'05 Reconstructed R'!$B$15*('05 Reconstructed R'!E29/B29-'05 Reconstructed R'!$B$10)/('01 Traffic inputs'!$B$10-'05 Reconstructed R'!$B$15))*60 -> 0.90836871 | D29: ='01 Traffic inputs'!$B$10*('05 Reconstructed R'!E29/B29-'05 Reconstructed R'!$B$10)/('01 Traffic inputs'!$B$10-'05 Reconstructed R'!$B$15)*60 -> 0.30252837 | E29: ='05 Reconstructed R'!D29 -> 51.532043 | F29: =B29*(C29+D29)/60 -> 2.1093995 | G29: =B29*C29/60*$B$8 -> 32621.994 | H29: =B29*D29/60*$C$8 -> 3653.1427 | I29: =J29/F29 -> 17196.902 | J29: =G29+H29 -> 36275.136 | K29: =B29*C29/60*$B$9 -> 48.01666 | L29: =B29*D29/60*$C$9 -> 2.1480233 | M29: =N29/F29 -> 23.781499 | N29: =K29+L29 -> 50.164683 | O29: =B29*C29/60*$B$10 -> 213.84077 | P29: =B29*D29/60*$C$10 -> 33.033231 | Q29: =R29/F29 -> 117.0352 | R29: =O29+P29 -> 246.874 | S29: =B29*C29/60*$B$11 -> 8.6560423 | T29: =B29*D29/60*$C$11 -> 1.4500151 | U29: =V29/F29 -> 4.7909641 | V29: =S29+T29 -> 10.106057
A30: ='03 Recorded O'!A17 -> 0.63541667 | B30: ='03 Recorded O'!B17 -> 102.27083 | C30: =('05 Reconstructed R'!$B$10-'05 Reconstructed R'!$B$15*('05 Reconstructed R'!E30/B30-'05 Reconstructed R'!$B$10)/('01 Traffic inputs'!$B$10-'05 Reconstructed R'!$B$15))*60 -> 0.87456974 | D30: ='01 Traffic inputs'!$B$10*('05 Reconstructed R'!E30/B30-'05 Reconstructed R'!$B$10)/('01 Traffic inputs'!$B$10-'05 Reconstructed R'!$B$15)*60 -> 0.46185062 | E30: ='05 Reconstructed R'!D30 -> 46.691896 | F30: =B30*(C30+D30)/60 -> 2.2779471 | G30: =B30*C30/60*$B$8 -> 30732.063 | H30: =B30*D30/60*$C$8 -> 5456.9629 | I30: =J30/F30 -> 15886.684 | J30: =G30+H30 -> 36189.025 | K30: =B30*C30/60*$B$9 -> 45.234851 | L30: =B30*D30/60*$C$9 -> 3.2086573 | M30: =N30/F30 -> 21.266301 | N30: =K30+L30 -> 48.443508 | O30: =B30*C30/60*$B$10 -> 201.45206 | P30: =B30*D30/60*$C$10 -> 49.344121 | Q30: =R30/F30 -> 110.09746 | R30: =O30+P30 -> 250.79618 | S30: =B30*C30/60*$B$11 -> 8.1545609 | T30: =B30*D30/60*$C$11 -> 2.1659922 | U30: =V30/F30 -> 4.5306378 | V30: =S30+T30 -> 10.320553
A31: ='03 Recorded O'!A18 -> 0.63888889 | B31: ='03 Recorded O'!B18 -> 102.875 | C31: =('05 Reconstructed R'!$B$10-'05 Reconstructed R'!$B$15*('05 Reconstructed R'!E31/B31-'05 Reconstructed R'!$B$10)/('01 Traffic inputs'!$B$10-'05 Reconstructed R'!$B$15))*60 -> 0.83351433 | D31: ='01 Traffic inputs'!$B$10*('05 Reconstructed R'!E31/B31-'05 Reconstructed R'!$B$10)/('01 Traffic inputs'!$B$10-'05 Reconstructed R'!$B$15)*60 -> 0.6553784 | E31: ='05 Reconstructed R'!D31 -> 41.91034 | F31: =B31*(C31+D31)/60 -> 2.5528307 | G31: =B31*C31/60*$B$8 -> 29462.418 | H31: =B31*D31/60*$C$8 -> 7789.3218 | I31: =J31/F31 -> 14592.327 | J31: =G31+H31 -> 37251.74 | K31: =B31*C31/60*$B$9 -> 43.366047 | L31: =B31*D31/60*$C$9 -> 4.5800686 | M31: =N31/F31 -> 18.78155 | N31: =K31+L31 -> 47.946116 | O31: =B31*C31/60*$B$10 -> 193.1294 | P31: =B31*D31/60*$C$10 -> 70.434277 | Q31: =R31/F31 -> 103.2437 | R31: =O31+P31 -> 263.56368 | S31: =B31*C31/60*$B$11 -> 7.8176686 | T31: =B31*D31/60*$C$11 -> 3.0917582 | U31: =V31/F31 -> 4.2734628 | V31: =S31+T31 -> 10.909427
